<sdf version='1.7'>
  <model name='vehicle'>
    <link name='vehicle'>
      <inertial>
        <pose>0.012549 0.002158 0.039696 0 -0 0</pose>
        <mass>4.574</mass>
        <inertia>
          <ixx>0.219171</ixx>
          <ixy>-0.00101314</ixy>
          <ixz>-0.0158164</ixz>
          <iyy>0.475754</iyy>
          <iyz>-0.00274192</iyz>
          <izz>0.592759</izz>
        </inertia>
      </inertial>
      <collision name='vehicle_fixed_joint_lump__base_link_collision'>
        <pose>0 0 0.2 0 -0 0</pose>
        <geometry>
          <box>
            <size>0.53 0.14 0.01</size>
          </box>
        </geometry>
      </collision>
      <collision name='vehicle_fixed_joint_lump__camera_link_collision_1'>
        <pose>0.1 0 0.3175 0 -0 0</pose>
        <geometry>
          <box>
            <size>0.02505 0.09 0.025</size>
          </box>
        </geometry>
        <surface>
          <contact>
            <ode>
              <kp>1e+13</kp>
              <kd>1</kd>
            </ode>
          </contact>
          <friction>
            <ode>
              <mu2>1</mu2>
              <fdir1>0 0 0</fdir1>
            </ode>
          </friction>
        </surface>
      </collision>
      <collision name='vehicle_fixed_joint_lump__camera_pole_link_collision_2'>
        <pose>0.1 0 0.25 0 -0 0</pose>
        <geometry>
          <box>
            <size>0.01 0.01 0.1</size>
          </box>
        </geometry>
      </collision>
      <visual name='vehicle_visual'>
        <pose>0 0 0.2 0 -0 0</pose>
        <geometry>
          <box>
            <size>0.01 0.01 0.01</size>
          </box>
        </geometry>
      </visual>
      <visual name='vehicle_fixed_joint_lump__base_link_visual_1'>
        <pose>0 0 0.2 0 -0 0</pose>
        <geometry>
          <mesh>
            <scale>1 1 1</scale>
            <uri>model://autonomous_vehicle_description/meshes/Base.stl</uri>
          </mesh>
        </geometry>
      </visual>
      <visual name='vehicle_fixed_joint_lump__camera_link_visual_2'>
        <pose>0.1149 0 0.3175 1.5708 -0 1.5708</pose>
        <geometry>
          <mesh>
            <scale>1 1 1</scale>
            <uri>model://realsense2_description/meshes/d435.dae</uri>
          </mesh>
        </geometry>
      </visual>
      <visual name='vehicle_fixed_joint_lump__camera_pole_link_visual_3'>
        <pose>0.1 0 0.25 0 -0 0</pose>
        <geometry>
          <box>
            <size>0.01 0.01 0.1</size>
          </box>
        </geometry>
      </visual>
      <self_collide>0</self_collide>
      <enable_wind>0</enable_wind>
      <kinematic>0</kinematic>
      <gravity>1</gravity>
      <sensor name='cameracolor' type='camera'>
        <camera name='camera'>
          <horizontal_fov>1.21126</horizontal_fov>
          <image>
            <width>640</width>
            <height>480</height>
            <format>RGB_INT8</format>
          </image>
          <clip>
            <near>0.1</near>
            <far>100</far>
          </clip>
          <noise>
            <type>gaussian</type>
            <mean>0</mean>
            <stddev>0.007</stddev>
          </noise>
        </camera>
        <always_on>1</always_on>
        <update_rate>30</update_rate>
        <visualize>1</visualize>
        <pose>0.1 0.0175 0.3175 0 -0 0</pose>
      </sensor>
      <sensor name='cameraired1' type='camera'>
        <camera name='camera'>
          <horizontal_fov>1.48702</horizontal_fov>
          <image>
            <width>1280</width>
            <height>720</height>
            <format>L_INT8</format>
          </image>
          <clip>
            <near>0.1</near>
            <far>100</far>
          </clip>
          <noise>
            <type>gaussian</type>
            <mean>0</mean>
            <stddev>0.05</stddev>
          </noise>
        </camera>
        <always_on>1</always_on>
        <update_rate>90</update_rate>
        <visualize>0</visualize>
        <pose>0.1 0.0175 0.3175 0 -0 0</pose>
      </sensor>
      <sensor name='cameraired2' type='camera'>
        <camera name='camera'>
          <horizontal_fov>1.48702</horizontal_fov>
          <image>
            <width>1280</width>
            <height>720</height>
            <format>L_INT8</format>
          </image>
          <clip>
            <near>0.1</near>
            <far>100</far>
          </clip>
          <noise>
            <type>gaussian</type>
            <mean>0</mean>
            <stddev>0.05</stddev>
          </noise>
        </camera>
        <always_on>1</always_on>
        <update_rate>90</update_rate>
        <visualize>0</visualize>
        <pose>0.1 0.0175 0.3175 0 -0 0</pose>
      </sensor>
      <sensor name='cameradepth' type='depth'>
        <camera name='camera'>
          <horizontal_fov>1.48702</horizontal_fov>
          <image>
            <width>1280</width>
            <height>720</height>
          </image>
          <clip>
            <near>0.1</near>
            <far>100</far>
          </clip>
          <noise>
            <type>gaussian</type>
            <mean>0</mean>
            <stddev>0.1</stddev>
          </noise>
        </camera>
        <always_on>1</always_on>
        <update_rate>90</update_rate>
        <visualize>0</visualize>
        <pose>0.1 0.0175 0.3175 0 -0 0</pose>
      </sensor>
    </link>
    <joint name='axle_left_rotate_joint' type='revolute'>
      <pose relative_to='vehicle'>-0.185 0.1025 0.2 0 -0 0</pose>
      <parent>vehicle</parent>
      <child>left_axle</child>
      <axis>
        <xyz>0 0 1</xyz>
        <limit>
          <lower>-0.35</lower>
          <upper>0.35</upper>
          <effort>1000</effort>
          <velocity>0.5</velocity>
        </limit>
        <dynamics>
          <spring_reference>0</spring_reference>
          <spring_stiffness>0</spring_stiffness>
        </dynamics>
      </axis>
    </joint>
    <link name='left_axle'>
      <pose relative_to='axle_left_rotate_joint'>0 0 0 0 -0 0</pose>
      <inertial>
        <pose>0 0 0 0 -0 0</pose>
        <mass>0.01</mass>
        <inertia>
          <ixx>0.001</ixx>
          <ixy>0</ixy>
          <ixz>0</ixz>
          <iyy>0.001</iyy>
          <iyz>0</iyz>
          <izz>0.001</izz>
        </inertia>
      </inertial>
      <visual name='left_axle_visual'>
        <pose>0 0 0 0 -0 0</pose>
        <geometry>
          <box>
            <size>0.01 0.01 0.01</size>
          </box>
        </geometry>
      </visual>
    </link>
    <joint name='wheel_left_rotate_joint' type='revolute'>
      <pose relative_to='left_axle'>0 0.0475 0 0 -0 0</pose>
      <parent>left_axle</parent>
      <child>LeftWheel_Front</child>
      <axis>
        <xyz>0 1 0</xyz>
        <limit>
          <lower>-1e+16</lower>
          <upper>1e+16</upper>
        </limit>
        <dynamics>
          <spring_reference>0</spring_reference>
          <spring_stiffness>0</spring_stiffness>
        </dynamics>
      </axis>
    </joint>
    <link name='LeftWheel_Front'>
      <pose relative_to='wheel_left_rotate_joint'>0 0 0 0 -0 0</pose>
      <inertial>
        <pose>0 0 0 0 -0 0</pose>
        <mass>1</mass>
        <inertia>
          <ixx>0.073454</ixx>
          <ixy>0</ixy>
          <ixz>0</ixz>
          <iyy>0.116212</iyy>
          <iyz>0</iyz>
          <izz>0.073454</izz>
        </inertia>
      </inertial>
      <collision name='LeftWheel_Front_collision'>
        <pose>0 0 0 1.5708 -0 0</pose>
        <geometry>
          <cylinder>
            <length>0.067</length>
            <radius>0.062</radius>
          </cylinder>
        </geometry>
      </collision>
      <visual name='LeftWheel_Front_visual'>
        <pose>0 0 0 0 -0 0</pose>
        <geometry>
          <mesh>
            <scale>1 1 1</scale>
            <uri>model://autonomous_vehicle_description/meshes/LeftWheel.stl</uri>
          </mesh>
        </geometry>
      </visual>
    </link>
    <joint name='axle_right_rotate_joint' type='revolute'>
      <pose relative_to='vehicle'>-0.185 -0.1025 0.2 0 -0 0</pose>
      <parent>vehicle</parent>
      <child>right_axle</child>
      <axis>
        <xyz>0 0 1</xyz>
        <limit>
          <lower>-0.35</lower>
          <upper>0.35</upper>
          <effort>1000</effort>
          <velocity>0.5</velocity>
        </limit>
        <dynamics>
          <spring_reference>0</spring_reference>
          <spring_stiffness>0</spring_stiffness>
        </dynamics>
      </axis>
    </joint>
    <link name='right_axle'>
      <pose relative_to='axle_right_rotate_joint'>0 0 0 0 -0 0</pose>
      <inertial>
        <pose>0 0 0 0 -0 0</pose>
        <mass>0.01</mass>
        <inertia>
          <ixx>0.001</ixx>
          <ixy>0</ixy>
          <ixz>0</ixz>
          <iyy>0.001</iyy>
          <iyz>0</iyz>
          <izz>0.001</izz>
        </inertia>
      </inertial>
      <visual name='right_axle_visual'>
        <pose>0 0 0 0 -0 0</pose>
        <geometry>
          <box>
            <size>0.01 0.01 0.01</size>
          </box>
        </geometry>
      </visual>
    </link>
    <joint name='wheel_right_rotate_joint' type='revolute'>
      <pose relative_to='right_axle'>0 -0.0475 0 0 -0 0</pose>
      <parent>right_axle</parent>
      <child>RightWheel_Front</child>
      <axis>
        <xyz>0 1 0</xyz>
        <limit>
          <lower>-1e+16</lower>
          <upper>1e+16</upper>
        </limit>
        <dynamics>
          <spring_reference>0</spring_reference>
          <spring_stiffness>0</spring_stiffness>
        </dynamics>
      </axis>
    </joint>
    <link name='RightWheel_Front'>
      <pose relative_to='wheel_right_rotate_joint'>0 0 0 0 -0 0</pose>
      <inertial>
        <pose>0 0 0 0 -0 0</pose>
        <mass>1</mass>
        <inertia>
          <ixx>0.073454</ixx>
          <ixy>0</ixy>
          <ixz>0</ixz>
          <iyy>0.116212</iyy>
          <iyz>0</iyz>
          <izz>0.073454</izz>
        </inertia>
      </inertial>
      <collision name='RightWheel_Front_collision'>
        <pose>0 0 0 1.5708 -0 0</pose>
        <geometry>
          <cylinder>
            <length>0.067</length>
            <radius>0.062</radius>
          </cylinder>
        </geometry>
      </collision>
      <visual name='RightWheel_Front_visual'>
        <pose>0 0 0 0 -0 0</pose>
        <geometry>
          <mesh>
            <scale>1 1 1</scale>
            <uri>model://autonomous_vehicle_description/meshes/RightWheel.stl</uri>
          </mesh>
        </geometry>
      </visual>
    </link>
    <joint name='LeftWheel_joint' type='revolute'>
      <pose relative_to='vehicle'>0.185 0.15 0.2 0 -0 0</pose>
      <parent>vehicle</parent>
      <child>LeftWheel_Back</child>
      <axis>
        <xyz>0 1 0</xyz>
        <limit>
          <lower>-1e+16</lower>
          <upper>1e+16</upper>
        </limit>
        <dynamics>
          <spring_reference>0</spring_reference>
          <spring_stiffness>0</spring_stiffness>
        </dynamics>
      </axis>
    </joint>
    <link name='LeftWheel_Back'>
      <pose relative_to='LeftWheel_joint'>0 0 0 0 -0 0</pose>
      <inertial>
        <pose>0 0 0 0 -0 0</pose>
        <mass>1</mass>
        <inertia>
          <ixx>0.073454</ixx>
          <ixy>0</ixy>
          <ixz>0</ixz>
          <iyy>0.116212</iyy>
          <iyz>0</iyz>
          <izz>0.073454</izz>
        </inertia>
      </inertial>
      <collision name='LeftWheel_Back_collision'>
        <pose>0 0 0 1.5708 -0 0</pose>
        <geometry>
          <cylinder>
            <length>0.067</length>
            <radius>0.062</radius>
          </cylinder>
        </geometry>
      </collision>
      <visual name='LeftWheel_Back_visual'>
        <pose>0 0 0 0 -0 0</pose>
        <geometry>
          <mesh>
            <scale>1 1 1</scale>
            <uri>model://autonomous_vehicle_description/meshes/LeftWheel.stl</uri>
          </mesh>
        </geometry>
      </visual>
    </link>
    <joint name='RightWheel_joint' type='revolute'>
      <pose relative_to='vehicle'>0.185 -0.15 0.2 0 -0 0</pose>
      <parent>vehicle</parent>
      <child>RightWheel_Back</child>
      <axis>
        <xyz>0 1 0</xyz>
        <limit>
          <lower>-1e+16</lower>
          <upper>1e+16</upper>
        </limit>
        <dynamics>
          <spring_reference>0</spring_reference>
          <spring_stiffness>0</spring_stiffness>
        </dynamics>
      </axis>
    </joint>
    <link name='RightWheel_Back'>
      <pose relative_to='RightWheel_joint'>0 0 0 0 -0 0</pose>
      <inertial>
        <pose>0 0 0 0 -0 0</pose>
        <mass>1</mass>
        <inertia>
          <ixx>0.073454</ixx>
          <ixy>0</ixy>
          <ixz>0</ixz>
          <iyy>0.116212</iyy>
          <iyz>0</iyz>
          <izz>0.073454</izz>
        </inertia>
      </inertial>
      <collision name='RightWheel_Back_collision'>
        <pose>0 0 0 1.5708 -0 0</pose>
        <geometry>
          <cylinder>
            <length>0.067</length>
            <radius>0.062</radius>
          </cylinder>
        </geometry>
      </collision>
      <visual name='RightWheel_Back_visual'>
        <pose>0 0 0 0 -0 0</pose>
        <geometry>
          <mesh>
            <scale>1 1 1</scale>
            <uri>model://autonomous_vehicle_description/meshes/RightWheel.stl</uri>
          </mesh>
        </geometry>
      </visual>
    </link>
    <plugin name='camera' filename='librealsense_gazebo_plugin.so'>
      <prefix>camera</prefix>
      <depthUpdateRate>30.0</depthUpdateRate>
      <colorUpdateRate>30.0</colorUpdateRate>
      <infraredUpdateRate>30.0</infraredUpdateRate>
      <depthTopicName>depth/image_raw</depthTopicName>
      <depthCameraInfoTopicName>depth/camera_info</depthCameraInfoTopicName>
      <colorTopicName>color/image_raw</colorTopicName>
      <colorCameraInfoTopicName>color/camera_info</colorCameraInfoTopicName>
      <infrared1TopicName>infra1/image_raw</infrared1TopicName>
      <infrared1CameraInfoTopicName>infra1/camera_info</infrared1CameraInfoTopicName>
      <infrared2TopicName>infra2/image_raw</infrared2TopicName>
      <infrared2CameraInfoTopicName>infra2/camera_info</infrared2CameraInfoTopicName>
      <colorOpticalframeName>camera_color_optical_frame</colorOpticalframeName>
      <depthOpticalframeName>camera_depth_optical_frame</depthOpticalframeName>
      <infrared1OpticalframeName>camera_left_ir_optical_frame</infrared1OpticalframeName>
      <infrared2OpticalframeName>camera_right_ir_optical_frame</infrared2OpticalframeName>
      <rangeMinDepth>0.2</rangeMinDepth>
      <rangeMaxDepth>10.0</rangeMaxDepth>
      <pointCloud>1</pointCloud>
      <pointCloudTopicName>depth/color/points</pointCloudTopicName>
      <pointCloudCutoff>0.25</pointCloudCutoff>
      <pointCloudCutoffMax>9.0</pointCloudCutoffMax>
    </plugin>
    <static>0</static>
    <plugin name='gazebo_ros_control' filename='libgazebo_ros_control.so'>
      <robotNamespace>/</robotNamespace>
    </plugin>
  </model>
</sdf>
