<?xml version="1.0" ?>
<!-- =================================================================================== -->
<!-- |    This document was autogenerated by xacro from vehicle_modelV2.urdf.xacro     | -->
<!-- |    EDITING THIS FILE BY HAND IS NOT RECOMMENDED                                 | -->
<!-- =================================================================================== -->
<robot name="vehicle">
  <!--xacro:include filename="$(find autonomous_vehicle_description)/urdf/autonomous_vehicle.gazebo" /-->
  <link name="vehicle">
    <visual>
      <origin rpy="0 0 0" xyz="0 0 0.2"/>
      <geometry>
        <box size="0.01 0.01 0.01"/>
      </geometry>
    </visual>
  </link>
  <link name="base_link">
    <visual>
      <origin xyz="0 0 0.2"/>
      <geometry>
        <mesh filename="package://autonomous_vehicle_description/meshes/Base.stl"/>
      </geometry>
    </visual>
    <collision>
      <origin xyz="0 0 0.2"/>
      <geometry>
        <box size="0.53 0.14 0.01"/>
      </geometry>
    </collision>
    <inertial>
      <mass value="4"/>
      <inertia ixx="0.163866" ixy="-0.000150" ixz="0.000062" iyy="0.418963" iyz="0.000000" izz="0.582709"/>
    </inertial>
  </link>
  <link name="camera_pole_link">
    <visual>
      <geometry>
        <box size="0.01 0.01 0.1"/>
      </geometry>
    </visual>
    <collision>
      <geometry>
        <box size="0.01 0.01 0.1"/>
      </geometry>
    </collision>
    <inertial>
      <mass value="0.01"/>
      <inertia ixx="0.001" ixy="0.000000" ixz="0.000000" iyy="0.001" iyz="0.000000" izz="0.001"/>
    </inertial>
  </link>
  <joint name="vehicle_camera_pole_joint" type="fixed">
    <parent link="base_link"/>
    <child link="camera_pole_link"/>
    <origin xyz="0.1 0 0.25"/>
  </joint>
  <link name="camera_link">
    <visual>
      <geometry>
        <box size="0.01 0.01 0.01"/>
      </geometry>
    </visual>
    <collision>
      <geometry>
        <box size="0.01 0.01 0.01"/>
      </geometry>
    </collision>
    <inertial>
      <mass value="0.01"/>
      <inertia ixx="0.001" ixy="0.000000" ixz="0.000000" iyy="0.001" iyz="0.000000" izz="0.001"/>
    </inertial>
  </link>
  <joint name="vahicle_camera_pole_joint" type="fixed">
    <parent link="camera_pole_link"/>
    <child link="camera_link"/>
    <origin xyz="0 0 0.055"/>
  </joint>
  <joint name="vehicle_dummy_joint" type="fixed">
    <parent link="vehicle"/>
    <child link="base_link"/>
    <origin xyz="0 0 0"/>
  </joint>
  <link name="left_axle">
    <visual>
      <geometry>
        <box size="0.01 0.01 0.01"/>
      </geometry>
    </visual>
    <contact>
      <geometry>
        <box size="0.01 0.01 0.01"/>
      </geometry>
    </contact>
    <inertial>
      <mass value="0.01"/>
      <inertia ixx="0.001" ixy="0.000000" ixz="0.000000" iyy="0.001" iyz="0.000000" izz="0.001"/>
    </inertial>
  </link>
  <joint name="axle_left_rotate_joint" type="revolute">
    <axis xyz="0 0 1"/>
    <parent link="vehicle"/>
    <child link="left_axle"/>
    <origin xyz="-0.185 0.1025 0.2"/>
    <limit effort="1000.0" lower="-0.35" upper="0.35" velocity="0.5"/>
  </joint>
  <transmission name="axle_left_rotate_trans">
    <type>transmission_interface/SimpleTransmission</type>
    <actuator name="$axle_left_rotate_motor">
      <mechanicalReduction>1</mechanicalReduction>
    </actuator>
    <joint name="axle_left_rotate_joint">
      <hardwareInterface>PositionJointInterface</hardwareInterface>
    </joint>
  </transmission>
  <link name="right_axle">
    <visual>
      <geometry>
        <box size="0.01 0.01 0.01"/>
      </geometry>
    </visual>
    <contact>
      <geometry>
        <box size="0.01 0.01 0.01"/>
      </geometry>
    </contact>
    <inertial>
      <mass value="0.01"/>
      <inertia ixx="0.001" ixy="0.000000" ixz="0.000000" iyy="0.001" iyz="0.000000" izz="0.001"/>
    </inertial>
  </link>
  <joint name="axle_right_rotate_joint" type="revolute">
    <axis xyz="0 0 1"/>
    <parent link="vehicle"/>
    <child link="right_axle"/>
    <origin xyz="-0.185 -0.1025 0.2"/>
    <limit effort="1000.0" lower="-0.35" upper="0.35" velocity="0.5"/>
  </joint>
  <transmission name="axle_right_rotate_trans">
    <type>transmission_interface/SimpleTransmission</type>
    <actuator name="$axle_right_rotate_motor">
      <mechanicalReduction>1</mechanicalReduction>
    </actuator>
    <joint name="axle_right_rotate_joint">
      <hardwareInterface>PositionJointInterface</hardwareInterface>
    </joint>
  </transmission>
  <link name="RightWheel_Front">
    <visual>
      <!--origin xyz="0 0 ${VehicleHeight}"/-->
      <geometry>
        <mesh filename="package://autonomous_vehicle_description/meshes/RightWheel.stl"/>
      </geometry>
    </visual>
    <collision>
      <origin rpy="1.5707963267948966 0 0"/>
      <geometry>
        <cylinder length="0.0670" radius="0.0620"/>
      </geometry>
    </collision>
    <inertial>
      <mass value="1"/>
      <inertia ixx="0.073454" ixy="0.000000" ixz="-0.000000" iyy="0.116212" iyz="0.000000" izz="0.073454"/>
    </inertial>
  </link>
  <link name="LeftWheel_Front">
    <visual>
      <!--origin xyz="0 0 ${VehicleHeight}"/-->
      <geometry>
        <mesh filename="package://autonomous_vehicle_description/meshes/LeftWheel.stl"/>
      </geometry>
    </visual>
    <collision>
      <origin rpy="1.5707963267948966 0 0"/>
      <geometry>
        <cylinder length="0.0670" radius="0.0620"/>
      </geometry>
    </collision>
    <inertial>
      <mass value="1"/>
      <inertia ixx="0.073454" ixy="0.000000" ixz="-0.000000" iyy="0.116212" iyz="0.000000" izz="0.073454"/>
    </inertial>
  </link>
  <link name="RightWheel_Back">
    <visual>
      <!--origin xyz="0 0 ${VehicleHeight}"/-->
      <geometry>
        <mesh filename="package://autonomous_vehicle_description/meshes/RightWheel.stl"/>
      </geometry>
    </visual>
    <collision>
      <origin rpy="1.5707963267948966 0 0"/>
      <geometry>
        <cylinder length="0.0670" radius="0.0620"/>
      </geometry>
    </collision>
    <inertial>
      <mass value="1"/>
      <inertia ixx="0.073454" ixy="0.000000" ixz="-0.000000" iyy="0.116212" iyz="0.000000" izz="0.073454"/>
    </inertial>
  </link>
  <joint name="RightWheel_joint" type="continuous">
    <axis xyz="0 1 0"/>
    <parent link="base_link"/>
    <child link="RightWheel_Back"/>
    <origin xyz="0.185 -0.15 0.2"/>
  </joint>
  <transmission name="RightWheel_motor_trans">
    <type>transmission_interface/SimpleTransmission</type>
    <actuator name="RightWheel_motor_motor">
      <mechanicalReduction>1</mechanicalReduction>
    </actuator>
    <joint name="RightWheel_joint">
      <hardwareInterface>VelocityJointInterface</hardwareInterface>
    </joint>
  </transmission>
  <link name="LeftWheel_Back">
    <visual>
      <!--origin xyz="0 0 ${VehicleHeight}"/-->
      <geometry>
        <mesh filename="package://autonomous_vehicle_description/meshes/LeftWheel.stl"/>
      </geometry>
    </visual>
    <collision>
      <origin rpy="1.5707963267948966 0 0"/>
      <geometry>
        <cylinder length="0.0670" radius="0.0620"/>
      </geometry>
    </collision>
    <inertial>
      <mass value="1"/>
      <inertia ixx="0.073454" ixy="0.000000" ixz="-0.000000" iyy="0.116212" iyz="0.000000" izz="0.073454"/>
    </inertial>
  </link>
  <joint name="LeftWheel_joint" type="continuous">
    <axis xyz="0 1 0"/>
    <parent link="base_link"/>
    <child link="LeftWheel_Back"/>
    <origin xyz="0.185 0.15 0.2"/>
  </joint>
  <transmission name="LeftWheel_motor_trans">
    <type>transmission_interface/SimpleTransmission</type>
    <actuator name="LeftWheel_motor_motor">
      <mechanicalReduction>1</mechanicalReduction>
    </actuator>
    <joint name="LeftWheel_joint">
      <hardwareInterface>VelocityJointInterface</hardwareInterface>
    </joint>
  </transmission>
  <joint name="wheel_right_rotate_joint" type="continuous">
    <axis xyz="0 1 0"/>
    <parent link="right_axle"/>
    <child link="RightWheel_Front"/>
    <origin xyz="0 -0.0475 0"/>
  </joint>
  <joint name="wheel_left_rotate_joint" type="continuous">
    <axis xyz="0 1 0"/>
    <parent link="left_axle"/>
    <child link="LeftWheel_Front"/>
    <origin xyz="0 0.0475 0"/>
  </joint>
  <gazebo>
    <plugin filename="libgazebo_ros_control.so" name="gazebo_ros_control">
      <robotNamespace>/</robotNamespace>
    </plugin>
  </gazebo>
</robot>

