<?xml version="1.0" ?>
<!-- =================================================================================== -->
<!-- |    This document was autogenerated by xacro from vehicle_modelV3.urdf.xacro     | -->
<!-- |    EDITING THIS FILE BY HAND IS NOT RECOMMENDED                                 | -->
<!-- =================================================================================== -->
<robot name="vehicle">
  <!--
    
    Graus de liberdade 35 -35
    Velocidade maxima: 1,5 m/s
    Aceleração maxima: 1,5 m/s^2

    210 entre eixos

    81 - 67 = 14 desde o eixo ate ao centro da roda

    =>Left Wheel

    LOG: 2     |  0.000001  -0.000000   0.000000 |
    LOG: 2     | -0.000000   0.000001  -0.000000 |
    LOG: 2     |  0.000000  -0.000000   0.000001 |

    ________________Factor of 10________________ 

    
    LOG: 2     |  0.073454   0.000000  -0.000000 |
    LOG: 2     |  0.000000   0.116212   0.000000 |
    LOG: 2     | -0.000000   0.000000   0.073454 |

    =>Right Wheel

    LOG: 2     |  0.000001   0.000000  -0.000000 |
    LOG: 2     |  0.000000   0.000001   0.000000 |
    LOG: 2     | -0.000000   0.000000   0.000001 |

    ________________Factor of 10________________ 

    
    LOG: 2     |  0.073454   0.000000  -0.000000 |
    LOG: 2     |  0.000000   0.116212   0.000000 |
    LOG: 2     | -0.000000   0.000000   0.073454 |

    =>Base

    LOG: 2     |  0.000002  -0.000000   0.000000 |
    LOG: 2     | -0.000000   0.000004   0.000000 |
    LOG: 2     |  0.000000   0.000000   0.000006 |

    ________________Factor of 10________________ 
   
    LOG: 2     |  0.163866  -0.000150   0.000062 |
    LOG: 2     | -0.000150   0.418963   0.000000 |
    LOG: 2     |  0.000062   0.000000   0.582709 |


!-->
  <link name="vehicle">
    <visual>
      <origin rpy="0 0 0" xyz="0 0 0.2"/>
      <geometry>
        <box size="0.01 0.01 0.01"/>
      </geometry>
    </visual>
  </link>
  <link name="base_link">
    <visual>
      <origin xyz="0 0 0.2"/>
      <geometry>
        <mesh filename="package://autonomous_vehicle_description/meshes/Base.stl"/>
      </geometry>
    </visual>
    <collision>
      <origin xyz="0 0 0.2"/>
      <geometry>
        <box size="0.53 0.14 0.01"/>
      </geometry>
    </collision>
    <inertial>
      <mass value="4"/>
      <inertia ixx="0.163866" ixy="-0.000150" ixz="0.000062" iyy="0.418963" iyz="0.000000" izz="0.582709"/>
    </inertial>
  </link>
  <link name="camera_pole_link">
    <visual>
      <geometry>
        <box size="0.01 0.01 0.1"/>
      </geometry>
    </visual>
    <collision>
      <geometry>
        <box size="0.01 0.01 0.1"/>
      </geometry>
    </collision>
    <inertial>
      <mass value="0.01"/>
      <inertia ixx="0.001" ixy="0.000000" ixz="0.000000" iyy="0.001" iyz="0.000000" izz="0.001"/>
    </inertial>
  </link>
  <joint name="vehicle_camera_pole_joint" type="fixed">
    <parent link="base_link"/>
    <child link="camera_pole_link"/>
    <origin xyz="0.1 0 0.25"/>
  </joint>
  <material name="camera_aluminum">
    <color rgba="0.5 0.5 0.5 1"/>
  </material>
  <!-- camera body, with origin at bottom screw mount -->
  <joint name="camera_joint" type="fixed">
    <origin rpy="0 0 0" xyz="0.1 0 0.30500000000000005"/>
    <parent link="base_link"/>
    <child link="camera_bottom_screw_frame"/>
  </joint>
  <link name="camera_bottom_screw_frame"/>
  <joint name="camera_link_joint" type="fixed">
    <origin rpy="0 0 0" xyz="0 0.0175 0.0125"/>
    <parent link="camera_bottom_screw_frame"/>
    <child link="camera_link"/>
  </joint>
  <link name="camera_link">
    <visual>
      <origin rpy="1.5707963267948966 0 1.5707963267948966" xyz="0.0149 -0.0175 0"/>
      <geometry>
        <!-- <box size="${d435_cam_width} ${d435_cam_height} ${d435_cam_depth}"/> -->
        <mesh filename="package://realsense2_description/meshes/d435.dae"/>
        <!--<mesh filename="package://realsense2_description/meshes/d435/d435.dae" />-->
      </geometry>
      <material name="camera_aluminum"/>
    </visual>
    <collision>
      <origin rpy="0 0 0" xyz="0 -0.0175 0"/>
      <geometry>
        <box size="0.02505 0.09 0.025"/>
      </geometry>
    </collision>
    <inertial>
      <!-- The following are not reliable values, and should not be used for modeling -->
      <mass value="0.564"/>
      <origin xyz="0 0 0"/>
      <inertia ixx="0.003881243" ixy="0.0" ixz="0.0" iyy="0.000498940" iyz="0.0" izz="0.003879257"/>
    </inertial>
  </link>
  <!-- camera depth joints and links -->
  <joint name="camera_depth_joint" type="fixed">
    <origin rpy="0 0 0" xyz="0 0 0"/>
    <parent link="camera_link"/>
    <child link="camera_depth_frame"/>
  </joint>
  <link name="camera_depth_frame"/>
  <joint name="camera_depth_optical_joint" type="fixed">
    <origin rpy="-1.5707963267948966 0 -1.5707963267948966" xyz="0 0 0"/>
    <parent link="camera_depth_frame"/>
    <child link="camera_depth_optical_frame"/>
  </joint>
  <link name="camera_depth_optical_frame"/>
  <!-- camera left IR joints and links -->
  <joint name="camera_left_ir_joint" type="fixed">
    <origin rpy="0 0 0" xyz="0 0.0 0"/>
    <parent link="camera_depth_frame"/>
    <child link="camera_left_ir_frame"/>
  </joint>
  <link name="camera_left_ir_frame"/>
  <joint name="camera_left_ir_optical_joint" type="fixed">
    <origin rpy="-1.5707963267948966 0 -1.5707963267948966" xyz="0 0 0"/>
    <parent link="camera_left_ir_frame"/>
    <child link="camera_left_ir_optical_frame"/>
  </joint>
  <link name="camera_left_ir_optical_frame"/>
  <!-- camera right IR joints and links -->
  <joint name="camera_right_ir_joint" type="fixed">
    <origin rpy="0 0 0" xyz="0 -0.05 0"/>
    <parent link="camera_depth_frame"/>
    <child link="camera_right_ir_frame"/>
  </joint>
  <link name="camera_right_ir_frame"/>
  <joint name="camera_right_ir_optical_joint" type="fixed">
    <origin rpy="-1.5707963267948966 0 -1.5707963267948966" xyz="0 0 0"/>
    <parent link="camera_right_ir_frame"/>
    <child link="camera_right_ir_optical_frame"/>
  </joint>
  <link name="camera_right_ir_optical_frame"/>
  <!-- camera color joints and links -->
  <joint name="camera_color_joint" type="fixed">
    <origin rpy="0 0 0" xyz="0 0.015 0"/>
    <parent link="camera_depth_frame"/>
    <child link="camera_color_frame"/>
  </joint>
  <link name="camera_color_frame"/>
  <joint name="camera_color_optical_joint" type="fixed">
    <origin rpy="-1.5707963267948966 0 -1.5707963267948966" xyz="0 0 0"/>
    <parent link="camera_color_frame"/>
    <child link="camera_color_optical_frame"/>
  </joint>
  <link name="camera_color_optical_frame"/>
  <gazebo reference="camera_link">
    <self_collide>0</self_collide>
    <enable_wind>0</enable_wind>
    <kinematic>0</kinematic>
    <gravity>1</gravity>
    <!--<mu>1</mu>-->
    <mu2>1</mu2>
    <fdir1>0 0 0</fdir1>
    <!--<slip1>0</slip1>
      <slip2>0</slip2>-->
    <kp>1e+13</kp>
    <kd>1</kd>
    <!--<max_vel>0.01</max_vel>
      <min_depth>0</min_depth>-->
    <sensor name="cameracolor" type="camera">
      <camera name="camera">
        <horizontal_fov>1.2112585008840648</horizontal_fov>
        <image>
          <width>640</width>
          <height>480</height>
          <format>RGB_INT8</format>
        </image>
        <clip>
          <near>0.1</near>
          <far>100</far>
        </clip>
        <noise>
          <type>gaussian</type>
          <mean>0.0</mean>
          <stddev>0.007</stddev>
        </noise>
      </camera>
      <always_on>1</always_on>
      <update_rate>30</update_rate>
      <visualize>1</visualize>
    </sensor>
    <sensor name="cameraired1" type="camera">
      <camera name="camera">
        <horizontal_fov>1.4870205226991688</horizontal_fov>
        <image>
          <width>1280</width>
          <height>720</height>
          <format>L_INT8</format>
        </image>
        <clip>
          <near>0.1</near>
          <far>100</far>
        </clip>
        <noise>
          <type>gaussian</type>
          <mean>0.0</mean>
          <stddev>0.05</stddev>
        </noise>
      </camera>
      <always_on>1</always_on>
      <update_rate>90</update_rate>
      <visualize>0</visualize>
    </sensor>
    <sensor name="cameraired2" type="camera">
      <camera name="camera">
        <horizontal_fov>1.4870205226991688</horizontal_fov>
        <image>
          <width>1280</width>
          <height>720</height>
          <format>L_INT8</format>
        </image>
        <clip>
          <near>0.1</near>
          <far>100</far>
        </clip>
        <noise>
          <type>gaussian</type>
          <mean>0.0</mean>
          <stddev>0.05</stddev>
        </noise>
      </camera>
      <always_on>1</always_on>
      <update_rate>90</update_rate>
      <visualize>0</visualize>
    </sensor>
    <sensor name="cameradepth" type="depth">
      <camera name="camera">
        <horizontal_fov>1.4870205226991688</horizontal_fov>
        <image>
          <width>1280</width>
          <height>720</height>
        </image>
        <clip>
          <near>0.1</near>
          <far>100</far>
        </clip>
        <noise>
          <type>gaussian</type>
          <mean>0.0</mean>
          <stddev>0.100</stddev>
        </noise>
      </camera>
      <always_on>1</always_on>
      <update_rate>90</update_rate>
      <visualize>0</visualize>
    </sensor>
  </gazebo>
  <gazebo>
    <plugin filename="librealsense_gazebo_plugin.so" name="camera">
      <prefix>camera</prefix>
      <depthUpdateRate>30.0</depthUpdateRate>
      <colorUpdateRate>30.0</colorUpdateRate>
      <infraredUpdateRate>30.0</infraredUpdateRate>
      <depthTopicName>depth/image_raw</depthTopicName>
      <depthCameraInfoTopicName>depth/camera_info</depthCameraInfoTopicName>
      <colorTopicName>color/image_raw</colorTopicName>
      <colorCameraInfoTopicName>color/camera_info</colorCameraInfoTopicName>
      <infrared1TopicName>infra1/image_raw</infrared1TopicName>
      <infrared1CameraInfoTopicName>infra1/camera_info</infrared1CameraInfoTopicName>
      <infrared2TopicName>infra2/image_raw</infrared2TopicName>
      <infrared2CameraInfoTopicName>infra2/camera_info</infrared2CameraInfoTopicName>
      <colorOpticalframeName>camera_color_optical_frame</colorOpticalframeName>
      <depthOpticalframeName>camera_depth_optical_frame</depthOpticalframeName>
      <infrared1OpticalframeName>camera_left_ir_optical_frame</infrared1OpticalframeName>
      <infrared2OpticalframeName>camera_right_ir_optical_frame</infrared2OpticalframeName>
      <rangeMinDepth>0.2</rangeMinDepth>
      <rangeMaxDepth>10.0</rangeMaxDepth>
      <pointCloud>True</pointCloud>
      <pointCloudTopicName>depth/color/points</pointCloudTopicName>
      <pointCloudCutoff>0.25</pointCloudCutoff>
      <pointCloudCutoffMax>9.0</pointCloudCutoffMax>
    </plugin>
  </gazebo>
  <!--joint name="vahicle_camera_pole_joint" type="fixed">
        <parent link="camera_pole_link"/>
        <child link="camera_link"/>
        <origin xyz="0 0 ${PoleHeight/2 + 0.01/2}"/>
    </joint-->
  <joint name="vehicle_dummy_joint" type="fixed">
    <parent link="vehicle"/>
    <child link="base_link"/>
    <origin xyz="0 0 0"/>
  </joint>
  <link name="left_axle">
    <visual>
      <geometry>
        <box size="0.01 0.01 0.01"/>
      </geometry>
    </visual>
    <contact>
      <geometry>
        <box size="0.01 0.01 0.01"/>
      </geometry>
    </contact>
    <inertial>
      <mass value="0.01"/>
      <inertia ixx="0.001" ixy="0.000000" ixz="0.000000" iyy="0.001" iyz="0.000000" izz="0.001"/>
    </inertial>
  </link>
  <joint name="axle_left_rotate_joint" type="revolute">
    <axis xyz="0 0 1"/>
    <parent link="vehicle"/>
    <child link="left_axle"/>
    <origin xyz="-0.185 0.1025 0.2"/>
    <limit effort="1000.0" lower="-0.35" upper="0.35" velocity="0.5"/>
  </joint>
  <transmission name="axle_left_rotate_trans">
    <type>transmission_interface/SimpleTransmission</type>
    <actuator name="$axle_left_rotate_motor">
      <mechanicalReduction>1</mechanicalReduction>
    </actuator>
    <joint name="axle_left_rotate_joint">
      <hardwareInterface>PositionJointInterface</hardwareInterface>
    </joint>
  </transmission>
  <link name="right_axle">
    <visual>
      <geometry>
        <box size="0.01 0.01 0.01"/>
      </geometry>
    </visual>
    <contact>
      <geometry>
        <box size="0.01 0.01 0.01"/>
      </geometry>
    </contact>
    <inertial>
      <mass value="0.01"/>
      <inertia ixx="0.001" ixy="0.000000" ixz="0.000000" iyy="0.001" iyz="0.000000" izz="0.001"/>
    </inertial>
  </link>
  <joint name="axle_right_rotate_joint" type="revolute">
    <axis xyz="0 0 1"/>
    <parent link="vehicle"/>
    <child link="right_axle"/>
    <origin xyz="-0.185 -0.1025 0.2"/>
    <limit effort="1000.0" lower="-0.35" upper="0.35" velocity="0.5"/>
  </joint>
  <transmission name="axle_right_rotate_trans">
    <type>transmission_interface/SimpleTransmission</type>
    <actuator name="$axle_right_rotate_motor">
      <mechanicalReduction>1</mechanicalReduction>
    </actuator>
    <joint name="axle_right_rotate_joint">
      <hardwareInterface>PositionJointInterface</hardwareInterface>
    </joint>
  </transmission>
  <link name="RightWheel_Front">
    <visual>
      <!--origin xyz="0 0 ${VehicleHeight}"/-->
      <geometry>
        <mesh filename="package://autonomous_vehicle_description/meshes/RightWheel.stl"/>
      </geometry>
    </visual>
    <collision>
      <origin rpy="1.5707963267948966 0 0"/>
      <geometry>
        <cylinder length="0.0670" radius="0.0620"/>
      </geometry>
    </collision>
    <inertial>
      <mass value="1"/>
      <inertia ixx="0.073454" ixy="0.000000" ixz="-0.000000" iyy="0.116212" iyz="0.000000" izz="0.073454"/>
    </inertial>
  </link>
  <link name="LeftWheel_Front">
    <visual>
      <!--origin xyz="0 0 ${VehicleHeight}"/-->
      <geometry>
        <mesh filename="package://autonomous_vehicle_description/meshes/LeftWheel.stl"/>
      </geometry>
    </visual>
    <collision>
      <origin rpy="1.5707963267948966 0 0"/>
      <geometry>
        <cylinder length="0.0670" radius="0.0620"/>
      </geometry>
    </collision>
    <inertial>
      <mass value="1"/>
      <inertia ixx="0.073454" ixy="0.000000" ixz="-0.000000" iyy="0.116212" iyz="0.000000" izz="0.073454"/>
    </inertial>
  </link>
  <link name="RightWheel_Back">
    <visual>
      <!--origin xyz="0 0 ${VehicleHeight}"/-->
      <geometry>
        <mesh filename="package://autonomous_vehicle_description/meshes/RightWheel.stl"/>
      </geometry>
    </visual>
    <collision>
      <origin rpy="1.5707963267948966 0 0"/>
      <geometry>
        <cylinder length="0.0670" radius="0.0620"/>
      </geometry>
    </collision>
    <inertial>
      <mass value="1"/>
      <inertia ixx="0.073454" ixy="0.000000" ixz="-0.000000" iyy="0.116212" iyz="0.000000" izz="0.073454"/>
    </inertial>
  </link>
  <joint name="RightWheel_joint" type="continuous">
    <axis xyz="0 1 0"/>
    <parent link="base_link"/>
    <child link="RightWheel_Back"/>
    <origin xyz="0.185 -0.15 0.2"/>
  </joint>
  <transmission name="RightWheel_motor_trans">
    <type>transmission_interface/SimpleTransmission</type>
    <actuator name="RightWheel_motor_motor">
      <mechanicalReduction>1</mechanicalReduction>
    </actuator>
    <joint name="RightWheel_joint">
      <hardwareInterface>VelocityJointInterface</hardwareInterface>
    </joint>
  </transmission>
  <link name="LeftWheel_Back">
    <visual>
      <!--origin xyz="0 0 ${VehicleHeight}"/-->
      <geometry>
        <mesh filename="package://autonomous_vehicle_description/meshes/LeftWheel.stl"/>
      </geometry>
    </visual>
    <collision>
      <origin rpy="1.5707963267948966 0 0"/>
      <geometry>
        <cylinder length="0.0670" radius="0.0620"/>
      </geometry>
    </collision>
    <inertial>
      <mass value="1"/>
      <inertia ixx="0.073454" ixy="0.000000" ixz="-0.000000" iyy="0.116212" iyz="0.000000" izz="0.073454"/>
    </inertial>
  </link>
  <joint name="LeftWheel_joint" type="continuous">
    <axis xyz="0 1 0"/>
    <parent link="base_link"/>
    <child link="LeftWheel_Back"/>
    <origin xyz="0.185 0.15 0.2"/>
  </joint>
  <transmission name="LeftWheel_motor_trans">
    <type>transmission_interface/SimpleTransmission</type>
    <actuator name="LeftWheel_motor_motor">
      <mechanicalReduction>1</mechanicalReduction>
    </actuator>
    <joint name="LeftWheel_joint">
      <hardwareInterface>VelocityJointInterface</hardwareInterface>
    </joint>
  </transmission>
  <joint name="wheel_right_rotate_joint" type="continuous">
    <axis xyz="0 1 0"/>
    <parent link="right_axle"/>
    <child link="RightWheel_Front"/>
    <origin xyz="0 -0.0475 0"/>
  </joint>
  <joint name="wheel_left_rotate_joint" type="continuous">
    <axis xyz="0 1 0"/>
    <parent link="left_axle"/>
    <child link="LeftWheel_Front"/>
    <origin xyz="0 0.0475 0"/>
  </joint>
  <gazebo>
    <plugin filename="libgazebo_ros_control.so" name="gazebo_ros_control">
      <robotNamespace>/</robotNamespace>
    </plugin>
  </gazebo>
</robot>

